Workbook

Sheet Campaign
A1: Gloomhaven: Jaws of the Lion Campaign Tracker
B3: Difficulty | D3: Level | E3: Party Members | G3: Scenario Level | I3: Scenario Metrics | L3: Difficulty | R3: Unlocked Items | W3: Secrets | Y3: Formula | Z3: Formula | AB3: Secrets
D4: =IF(NOT(OR(ISBLANK(Voidwarden!D2),Voidwarden!D2="<NAME>")),Voidwarden!S3,"-") -> - | E4: =IF(NOT(OR(ISBLANK(Voidwarden!D2),Voidwarden!D2="<NAME>")),Voidwarden!D2,"") | I4: Monster Level | J4: =G5 -> - | L4: 2 | R4: Items 1-13 | T4: Item 30 | Y4: =L11 -> FALSE | Z4: =O33 -> FALSE | AB4: =Hatchet!$S3>=5 -> FALSE
D5: =IF(NOT(OR(ISBLANK(Demolitionist!D2),Demolitionist!D2="<NAME>")),Demolitionist!S3,"-") -> - | E5: =IF(NOT(OR(ISBLANK(Demolitionist!D2),Demolitionist!D2="<NAME>")),Demolitionist!D2,"") | G5: =IF(AND(D4="-",D5="-",D6="-",D7="-"),"-",ROUNDUP(AVERAGE(D4:D7)/2,0)+L4-2) -> - | I5: Gold Conversion | J5: =IF(NOT(L10),"-",IF(OR(G5=0,G5=1),2,IF(OR(G5=2,G5=3),3,IF(OR(G5=4,G5=5),4,IF(G5=6,5,IF(G5=7,6,"-")))))) -> - | R5: Items 15-20 | T5: Item 31 | Y5: =L18 -> FALSE | Z5: =OR(O27,L31) -> FALSE | AB5: =Demolitionist!$S3>=5 -> FALSE
D6: =IF(NOT(OR(ISBLANK(Hatchet!D2),Hatchet!D2="<NAME>")),Hatchet!S3,"-") -> - | E6: =IF(NOT(OR(ISBLANK(Hatchet!D2),Hatchet!D2="<NAME>")),Hatchet!D2,"") | I6: Trap Damage | J6: =IF(OR(NOT(L10),G5="-"),"-",G5+2) -> - | R6: Items 21-26 | S6: =IF(AND(Y16,NOT(L24)),26,"") | T6: Item 32 | Y6: =L24 -> FALSE | Z6: FALSE | AB6: =Voidwarden!S3>=5 -> FALSE
D7: =IF(NOT(OR(ISBLANK('Red Guard'!D2),'Red Guard'!D2="<NAME>")),'Red Guard'!S3,"-") -> - | E7: =IF(NOT(OR(ISBLANK('Red Guard'!D2),'Red Guard'!D2="<NAME>")),'Red Guard'!D2,"") | I7: Bonus Experience | J7: =IF(OR(NOT(L10),NOT(L11),G5="-"),"-",(G5*2)+4) -> - | R7: Item 14 | S7: =IF(AND(OR(O13,L13),NOT(AND(O13,L13))),1/2,"") | T7: Item 33 | Y7: =OR(O13,L13) -> FALSE | Z7: =L34 -> FALSE | AB7: ='Red Guard'!$S3>=5 -> FALSE
R8: Item 27 | T8: Item 34 | Y8: =O12 -> FALSE | Z8: =L35 -> FALSE
B9: Unlocked | C9: Completed | D9: Scenario | E9: Scenario Name | G9: Location | H9: Chest | I9: Chest Contents | K9: Unlocked | L9: Completed | M9: Name | N9: Location | O9: Chest | P9: Chest Contents | R9: Item 28 | T9: Item 35 | Y9: =OR(L20,L21) -> FALSE | Z9: =L36 -> FALSE
D10: 1 | E10: =IF(K10,M10,"") -> Roadside Ambush | G10: =IF(K10,N10,"") -> B1 | K10: TRUE | L10: FALSE | M10: Roadside Ambush | N10: B1 | R10: Item 29 | T10: Item 36 | Y10: =L25 -> FALSE | Z10: =L37 -> FALSE
D11: 2 | E11: =IF(K11,M11,"") | G11: =IF(K11,N11,"") | I11: =IF(O11,P11,"") | K11: =L10 -> FALSE | L11: FALSE | M11: A Hole in the Wall | N11: B1 | O11: FALSE | P11: Gain 3 money tokens
D12: 3 | E12: =IF(K12,M12,"") | G12: =IF(K12,N12,"") | I12: =IF(O12,P12,"") | K12: =L11 -> FALSE | L12: FALSE | M12: The Black Ship | N12: D5 | O12: FALSE | P12: Fateful Compass (Item 27)
D13: 4 | E13: =IF(K13,M13,"") | G13: =IF(K13,N13,"") | I13: =IF(O13,P13,"") | K13: =L12 -> FALSE | L13: FALSE | M13: A Ritual in Stone | N13: C2 | O13: FALSE | P13: Mana Potion (Item 14)
D14: 5 | E14: =IF(K14,M14,"") | G14: =IF(K14,N14,"") | I14: =IF(O14,P14,"") | K14: =L13 -> FALSE | L14: FALSE | M14: A Deeper Understanding | N14: C2 | O14: FALSE | P14: Gain 5 gold
D15: 6 | E15: =IF(K15,M15,"") | G15: =IF(K15,N15,"") | K15: =L14 -> FALSE | L15: FALSE | M15: Corrupted Research | N15: B4 | R15: City Event | S15: Option A | T15: Option B | U15: City Event Result | Y15: Option A | Z15: Option A Result | AA15: Option B | AB15: Option B Result
D16: 7 | E16: =IF(L17,M16&" [CLOSED]",IF(K16,M16,"")) | G16: =IF(K16,N16,"") | I16: =IF(O16,P16,"") | K16: =L15 -> FALSE | L16: FALSE | M16: Sunken Tumor | N16: D2 | O16: FALSE | P16: Gain 5 gold | R16: Event 1 | U16: =IF(AND(Y16,AA16),"NICE TRY!",IF(Y16,Z16,IF(AA16,AB16,""))) | Y16: FALSE | Z16: Gain Oak Charm (Item 26). | AA16: FALSE | AB16: Gain 20 collective gold.
D17: 8 | E17: =IF(L16,M17&" [CLOSED]",IF(K17,M17,"")) | G17: =IF(K17,N17,"") | I17: =IF(O17,P17,"") | K17: =L15 -> FALSE | L17: FALSE | M17: Hidden Tumor | N17: C4 | O17: FALSE | P17: Gain 5 gold | R17: Event 2 | U17: =IF(AND(Y17,AA17),"NICE TRY!",IF(Y17,Z17,IF(AA17,AB17,""))) | Y17: FALSE | Z17: Each character gains BLESS. | AA17: FALSE | AB17: Each character gains BLESS. Gain Chain Armor (Item 03).
D18: 9 | E18: =IF(K18,M18,"") | G18: =IF(L16,N17,IF(L17,N16,"")) | I18: =IF(O18,P18,"") | K18: =OR(L16,L17) -> FALSE | L18: FALSE | M18: Explosive Evolution | N18: D2 or C4 | O18: FALSE | P18: Gain 10 experience | R18: Event 3 | U18: =IF(AND(Y18,AA18),"NICE TRY!",IF(Y18,Z18,IF(AA18,AB18,""))) | Y18: FALSE | Z18: Gain 5 collective gold. | AA18: FALSE | AB18: No effect.
D19: 10 | E19: =IF(K19,M19,"") | G19: =IF(K19,N19,"") | I19: =IF(O19,P19,"") | K19: =L18 -> FALSE | L19: FALSE | M19: The Gauntlet | N19: E2 | O19: FALSE | P19: Suffer 3 damage, gain POISON | R19: Event 4 | U19: =IF(AND(Y19,AA19),"NICE TRY!",IF(Y19,Z19,IF(AA19,AB19,""))) | Y19: FALSE | Z19: Gain 5 collective gold. | AA19: FALSE | AB19: No effect.
D20: 11 | E20: =IF(L21,M20&" [CLOSED]",IF(K20,M20,"")) | G20: =IF(K20,N20,"") | K20: =L19 -> FALSE | L20: FALSE | M20: Defiled Sewers | N20: D2 | R20: Event 5 | U20: =IF(AND(Y20,AA20),"NICE TRY!",IF(Y20,Z20,IF(AA20,AB20,""))) | Y20: FALSE | Z20: Gain 5 experience each. | AA20: FALSE | AB20: Gain 10 experience each.
D21: 12 | E21: =IF(L20,M21&" [CLOSED]",IF(K21,M21,"")) | G21: =IF(K21,N21,"") | K21: =L19 -> FALSE | L21: FALSE | M21: Beguiling Sewers | N21: B5 | R21: Event 6 | U21: =IF(AND(Y21,AA21),"NICE TRY!",IF(Y21,Z21,IF(AA21,AB21,""))) | Y21: FALSE | Z21: One character gains WOUND. Each character gains CURSE. | AA21: FALSE | AB21: One character loses 5 gold. All other characters gain 15 collective gold.
D22: 13 | E22: =IF(K22,M22,"") | G22: =IF(K22,N22,"") | I22: =IF(O22,P22,"") | K22: =L20 -> FALSE | L22: FALSE | M22: Vile Harvest | N22: D3 | O22: FALSE | P22: Gain 1 checkmark | R22: Event 7 | U22: =IF(AND(Y22,AA22),"NICE TRY!",IF(Y22,Z22,IF(AA22,AB22,""))) | Y22: FALSE | Z22: If you said 3: Gain 10 collective gold each. Else: Lose 5 collective gold each. | AA22: FALSE | AB22: Each character gains MUDDLE.
D23: 14 | E23: =IF(K23,M23,"") | G23: =IF(K23,N23,"") | I23: =IF(O23,P23,"") | K23: =L21 -> FALSE | L23: FALSE | M23: Toxic Harvest | N23: B4 | O23: FALSE | P23: Gain 1 checkmark | R23: Event 8 | U23: =IF(AND(Y23,AA23),"NICE TRY!",IF(Y23,Z23,IF(AA23,AB23,""))) | Y23: FALSE | Z23: Gain 10 experience each. | AA23: FALSE | AB23: No effect.
D24: 15 | E24: =IF(K24,M24,"") | G24: =IF(K24,N24,"") | K24: =OR(L22,L23) -> FALSE | L24: FALSE | M24: Tainted Blood | N24: C4 | R24: Event 9 | U24: =IF(AND(Y24,AA24),"NICE TRY!",IF(Y24,Z24,IF(AA24,AB24,""))) | Y24: FALSE | Z24: Gain 15 collective gold. | AA24: FALSE | AB24: Each character gains CURSE.
D25: 16 | E25: =IF(K25,M25,"") | G25: =IF(K25,N25,"") | K25: =L24 -> FALSE | L25: FALSE | M25: Mixed Results | N25: B4 | R25: Event 10 | U25: =IF(AND(Y25,AA25),"NICE TRY!",IF(Y25,Z25,IF(AA25,AB25,""))) | Y25: FALSE | Z25: Gain 4 collective gold. Each character gains POISON. | AA25: FALSE | AB25: Each character gains BLESS.
D26: 17 | E26: =IF(K26,M26,"") | G26: =IF(K26,N26,"") | I26: =IF(O26,P26,"") | K26: =L25 -> FALSE | L26: FALSE | M26: Red Twilight | N26: C6 | O26: FALSE | P26: Gain 15 experience | R26: Event 11 | U26: =IF(AND(Y26,AA26),"NICE TRY!",IF(Y26,Z26,IF(AA26,AB26,""))) | Y26: FALSE | Z26: 3 or less: Lose 5 gold. 4 or 5: Gain 5 gold. 6 or more: Gain 5 gold and BLESS. | AA26: FALSE | AB26: Each character gains CURSE.
D27: 18 | E27: =IF(K27,M27,"") | G27: =IF(K27,N27,"") | I27: =IF(O27,P27,"") | K27: =L21 -> FALSE | L27: FALSE | M27: The Heist | N27: A5 | O27: FALSE | P27: Ring of Strength (Item 31) | R27: Event 12 | U27: =IF(AND(Y27,AA27),"NICE TRY!",IF(Y27,Z27,IF(AA27,AB27,""))) | Y27: FALSE | Z27: Lose 5 collective gold. | AA27: FALSE | AB27: Gain 10 collective gold.
I28: =IF(O28,P28,"") | O28: FALSE | P28: Gain 10 gold | R28: Event 13 | U28: =IF(AND(Y28,AA28),"NICE TRY!",IF(Y28,Z28,IF(AA28,AB28,""))) | Y28: FALSE | Z28: Lose 5 collective gold. You may temporarily purchase items for 5 less gold. | AA28: FALSE | AB28: No effect.
I29: =IF(O29,P29,"") | O29: FALSE | P29: Gain 5 gold | R29: Event 14 | U29: =IF(AND(Y29,AA29),"NICE TRY!",IF(Y29,Z29,IF(AA29,AB29,""))) | Y29: FALSE | Z29: Lose 5 gold each. Each character gains BLESS. | AA29: FALSE | AB29: Each character gains CURSE.
I30: =IF(O30,P30,"") | O30: FALSE | P30: Gain 5 gold | R30: Event 15 | U30: =IF(AND(Y30,AA30),"NICE TRY!",IF(Y30,Z30,IF(AA30,AB30,""))) | Y30: FALSE | Z30: Lose 5 collective gold. Gain 5 experience each. | AA30: FALSE | AB30: Lose 5 collective gold.
D31: 19 | E31: =IF(K31,M31,"") | G31: =IF(K31,N31,"") | K31: =L20 -> FALSE | L31: FALSE | M31: Den of Thieves | N31: A5 | R31: Event 16 | U31: =IF(AND(Y31,AA31),"NICE TRY!",IF(Y31,Z31,IF(AA31,AB31,""))) | Y31: FALSE | Z31: Gain 10 collective gold. | AA31: FALSE | AB31: No effect.
D32: 20 | E32: =IF(K32,M32,"") | G32: =IF(K32,N32,"") | K32: =OR(Y32,AA32) -> FALSE | L32: FALSE | M32: Misplaced Goods | N32: C5 | R32: Event 17 | U32: =IF(AND(Y32,AA32),"NICE TRY!",IF(Y32,Z32,IF(AA32,AB32,""))) | Y32: FALSE | Z32: New Location: "Misplaced Goods" 20 (C5) | AA32: FALSE | AB32: Gain 5 collective gold. New Location: "Misplaced Goods" 20 (C5)
D33: 21 | E33: =IF(K33,M33,"") | G33: =IF(K33,N33,"") | I33: =IF(O33,P33,"") | K33: =OR(Y33,AA33) -> FALSE | L33: FALSE | M33: Agents of Chaos | N33: C9 | O33: FALSE | P33: Ring of Haste (Item 30) | R33: Event 18 | U33: =IF(AND(Y33,AA33),"NICE TRY!",IF(Y33,Z33,IF(AA33,AB33,""))) | Y33: FALSE | Z33: Gain 5 collective gold. New location: "Agents of Chaos" 21 (C9) | AA33: FALSE | AB33: New location: "Agents of Chaos" 21 (C9)
D34: 22 | E34: =IF(K34,M34,"") | G34: =IF(K34,N34,"") | K34: =Y34 -> FALSE | L34: FALSE | M34: Unfriendly Message | N34: D1 | R34: Event 19 | U34: =IF(AND(Y34,AA34),"NICE TRY!",IF(Y34,Z34,IF(AA34,AB34,""))) | Y34: FALSE | Z34: New Location: "Unfriendly Message" 22 (D1) | AA34: FALSE | AB34: Resolve another event card.
D35: 23 | E35: =IF(K35,M35,"") | G35: =IF(K35,N35,"") | K35: =Y35 -> FALSE | L35: FALSE | M35: Best of the Best | N35: B5 | R35: Event 20 | U35: =IF(AND(Y35,AA35),"NICE TRY!",IF(Y35,Z35,IF(AA35,AB35,""))) | Y35: FALSE | Z35: New Location: "Best of the Best" 23 (B5) | AA35: FALSE | AB35: Resolve another event card.
D36: 24 | E36: =IF(K36,M36,"") | G36: =IF(K36,N36,"") | K36: =Y36 -> FALSE | L36: FALSE | M36: Warding the Void | N36: A3 | R36: Event 21 | U36: =IF(AND(Y36,AA36),"NICE TRY!",IF(Y36,Z36,IF(AA36,AB36,""))) | Y36: FALSE | Z36: New Location: "Warding the Void" 24 (A3) | AA36: FALSE | AB36: Resolve another event card.
D37: 25 | E37: =IF(K37,M37,"") | G37: =IF(K37,N37,"") | K37: =Y37 -> FALSE | L37: FALSE | M37: The Greatest Job in the World | N37: C7 | R37: Event 22 | U37: =IF(AND(Y37,AA37),"NICE TRY!",IF(Y37,Z37,IF(AA37,AB37,""))) | Y37: FALSE | Z37: New Location: "The Greatest Job in the World" 25 (C7) | AA37: FALSE | AB37: Resolve another event card.

Sheet Voidwarden
D2: <NAME>
D3: Human Voidwarden | Q3: Level | S3: =IF(D5>=500,9,IF(D5>=420,8,IF(D5>=345,7,IF(D5>=275,6,IF(D5>=210,5,IF(D5>=150,4,IF(D5>=95,3,IF(D5>=45,2,1)))))))) -> 1
B5: XP | F5: Gold | J5: ="Available Perks: "&T6 -> Available Perks: 0 | M5: Inventory (see "Inventory" tab) | P5: Ability Cards | T5: Possible Perks | U5: Battle Goals | V5: Used Perks | W5: Ability Cards 1 | X5: Ability Cards 2
B6: Battle Goals | K6: Remove two -1 cards | M6: {=IFERROR(INDEX(Inventory!$B$5:$B$56,SMALL(IF($D$2=Inventory!$F$5:$F$56,ROW(Inventory!$F$5:$F$56)-4,""),1)),"")} | N6: {=IFERROR(INDEX(Inventory!$C$5:$C$56,SMALL(IF($D$2=Inventory!$F$5:$F$56,ROW(Inventory!$F$5:$F$56)-4,""),1)),"")} | T6: =ROUNDDOWN(COUNTIF(U6:U23,TRUE)/3,0)+COUNTIF(Campaign!L12,TRUE)+S3-1-COUNTIF(V6:V20,TRUE) -> 0 | U6: FALSE | V6: FALSE
K7: Remove one -2 card | M7: {=IFERROR(INDEX(Inventory!$B$5:$B$56,SMALL(IF($D$2=Inventory!$F$5:$F$56,ROW(Inventory!$F$5:$F$56)-4,""),2)),"")} | N7: {=IFERROR(INDEX(Inventory!$C$5:$C$56,SMALL(IF($D$2=Inventory!$F$5:$F$56,ROW(Inventory!$F$5:$F$56)-4,""),2)),"")} | U7: FALSE | V7: FALSE
K8: Replace one +0 card with one +1 DARK card | M8: {=IFERROR(INDEX(Inventory!$B$5:$B$56,SMALL(IF($D$2=Inventory!$F$5:$F$56,ROW(Inventory!$F$5:$F$56)-4,""),3)),"")} | N8: {=IFERROR(INDEX(Inventory!$C$5:$C$56,SMALL(IF($D$2=Inventory!$F$5:$F$56,ROW(Inventory!$F$5:$F$56)-4,""),3)),"")} | U8: FALSE | V8: FALSE
K9: Replace one +0 card with one +1 DARK card | M9: {=IFERROR(INDEX(Inventory!$B$5:$B$56,SMALL(IF($D$2=Inventory!$F$5:$F$56,ROW(Inventory!$F$5:$F$56)-4,""),4)),"")} | N9: {=IFERROR(INDEX(Inventory!$C$5:$C$56,SMALL(IF($D$2=Inventory!$F$5:$F$56,ROW(Inventory!$F$5:$F$56)-4,""),4)),"")} | U9: FALSE | V9: FALSE
B10: Modifier Deck | K10: Replace one +0 card with one +1 COLD card | M10: {=IFERROR(INDEX(Inventory!$B$5:$B$56,SMALL(IF($D$2=Inventory!$F$5:$F$56,ROW(Inventory!$F$5:$F$56)-4,""),5)),"")} | N10: {=IFERROR(INDEX(Inventory!$C$5:$C$56,SMALL(IF($D$2=Inventory!$F$5:$F$56,ROW(Inventory!$F$5:$F$56)-4,""),5)),"")} | U10: FALSE | V10: FALSE
B11: (2x): 1 | F11: NULL: 1 | K11: Replace one +0 card with one +1 COLD card | M11: {=IFERROR(INDEX(Inventory!$B$5:$B$56,SMALL(IF($D$2=Inventory!$F$5:$F$56,ROW(Inventory!$F$5:$F$56)-4,""),6)),"")} | N11: {=IFERROR(INDEX(Inventory!$C$5:$C$56,SMALL(IF($D$2=Inventory!$F$5:$F$56,ROW(Inventory!$F$5:$F$56)-4,""),6)),"")} | U11: FALSE | V11: FALSE
B12: (+2): 1 | F12: ="(-2): "&1-V7 -> (-2): 1 | K12: Replace one -1 card with one +0 HEAL ALLY card | M12: {=IFERROR(INDEX(Inventory!$B$5:$B$56,SMALL(IF($D$2=Inventory!$F$5:$F$56,ROW(Inventory!$F$5:$F$56)-4,""),7)),"")} | N12: {=IFERROR(INDEX(Inventory!$C$5:$C$56,SMALL(IF($D$2=Inventory!$F$5:$F$56,ROW(Inventory!$F$5:$F$56)-4,""),7)),"")} | U12: FALSE | V12: FALSE
B13: (+1): 5 | F13: ="(-1): "&5-(2*V6)-V12-V13 -> (-1): 5 | K13: Replace one -1 card with one +0 HEAL ALLY card | M13: {=IFERROR(INDEX(Inventory!$B$5:$B$56,SMALL(IF($D$2=Inventory!$F$5:$F$56,ROW(Inventory!$F$5:$F$56)-4,""),8)),"")} | N13: {=IFERROR(INDEX(Inventory!$C$5:$C$56,SMALL(IF($D$2=Inventory!$F$5:$F$56,ROW(Inventory!$F$5:$F$56)-4,""),8)),"")} | U13: FALSE | V13: FALSE
B14: ="(+3): "&0+V18 -> (+3): 0 | F14: ="(+0): "&6-V8-V9-V10-V11 -> (+0): 6 | K14: Add one +1 HEAL ALLY card | M14: {=IFERROR(INDEX(Inventory!$B$5:$B$56,SMALL(IF($D$2=Inventory!$F$5:$F$56,ROW(Inventory!$F$5:$F$56)-4,""),9)),"")} | N14: {=IFERROR(INDEX(Inventory!$C$5:$C$56,SMALL(IF($D$2=Inventory!$F$5:$F$56,ROW(Inventory!$F$5:$F$56)-4,""),9)),"")} | U14: FALSE | V14: FALSE
B15: ="(+1) DARK: "&0+V8+V9 -> (+1) DARK: 0 | F15: ="(+1) COLD: "&0+V10+V11 -> (+1) COLD: 0 | K15: Add one +1 HEAL ALLY card | M15: {=IFERROR(INDEX(Inventory!$B$5:$B$56,SMALL(IF($D$2=Inventory!$F$5:$F$56,ROW(Inventory!$F$5:$F$56)-4,""),10)),"")} | N15: {=IFERROR(INDEX(Inventory!$C$5:$C$56,SMALL(IF($D$2=Inventory!$F$5:$F$56,ROW(Inventory!$F$5:$F$56)-4,""),10)),"")} | U15: FALSE | V15: FALSE
B16: ="(+0) HEAL ALLY: "&0+V12+V13 -> (+0) HEAL ALLY: 0 | K16: Add one +1 HEAL ALLY card | M16: {=IFERROR(INDEX(Inventory!$B$5:$B$56,SMALL(IF($D$2=Inventory!$F$5:$F$56,ROW(Inventory!$F$5:$F$56)-4,""),11)),"")} | N16: {=IFERROR(INDEX(Inventory!$C$5:$C$56,SMALL(IF($D$2=Inventory!$F$5:$F$56,ROW(Inventory!$F$5:$F$56)-4,""),11)),"")} | U16: FALSE | V16: FALSE
B17: ="(+1) HEAL ALLY: "&0+V14+V15+V16 -> (+1) HEAL ALLY: 0 | K17: Add one +1 POISON card | M17: {=IFERROR(INDEX(Inventory!$B$5:$B$56,SMALL(IF($D$2=Inventory!$F$5:$F$56,ROW(Inventory!$F$5:$F$56)-4,""),12)),"")} | N17: {=IFERROR(INDEX(Inventory!$C$5:$C$56,SMALL(IF($D$2=Inventory!$F$5:$F$56,ROW(Inventory!$F$5:$F$56)-4,""),12)),"")} | U17: FALSE | V17: FALSE
B18: ="(+1) POISON: "&0+V17 -> (+1) POISON: 0 | K18: Add one +3 card | M18: {=IFERROR(INDEX(Inventory!$B$5:$B$56,SMALL(IF($D$2=Inventory!$F$5:$F$56,ROW(Inventory!$F$5:$F$56)-4,""),13)),"")} | N18: {=IFERROR(INDEX(Inventory!$C$5:$C$56,SMALL(IF($D$2=Inventory!$F$5:$F$56,ROW(Inventory!$F$5:$F$56)-4,""),13)),"")} | U18: FALSE | V18: FALSE
B19: ="(+1) CURSE: "&0+V19+V20 -> (+1) CURSE: 0 | K19: Add one +1 CURSE card | M19: {=IFERROR(INDEX(Inventory!$B$5:$B$56,SMALL(IF($D$2=Inventory!$F$5:$F$56,ROW(Inventory!$F$5:$F$56)-4,""),14)),"")} | N19: {=IFERROR(INDEX(Inventory!$C$5:$C$56,SMALL(IF($D$2=Inventory!$F$5:$F$56,ROW(Inventory!$F$5:$F$56)-4,""),14)),"")} | U19: FALSE | V19: FALSE
B20: ="TOTAL CARDS: "&20-(2*V6)-V7+V14+V15+V16+V17+V18+V19+V20 -> TOTAL CARDS: 20 | K20: Add one +1 CURSE card | M20: {=IFERROR(INDEX(Inventory!$B$5:$B$56,SMALL(IF($D$2=Inventory!$F$5:$F$56,ROW(Inventory!$F$5:$F$56)-4,""),15)),"")} | N20: {=IFERROR(INDEX(Inventory!$C$5:$C$56,SMALL(IF($D$2=Inventory!$F$5:$F$56,ROW(Inventory!$F$5:$F$56)-4,""),15)),"")} | U20: FALSE | V20: FALSE
U21: FALSE
U22: FALSE
U23: FALSE

Sheet Demolitionist
D2: <NAME>
D3: Quatryl Demolitionist | Q3: Level | S3: =IF(D5>=500,9,IF(D5>=420,8,IF(D5>=345,7,IF(D5>=275,6,IF(D5>=210,5,IF(D5>=150,4,IF(D5>=95,3,IF(D5>=45,2,1)))))))) -> 1
B5: XP | F5: Gold | J5: ="Available Perks: "&T6 -> Available Perks: 0 | M5: Inventory (see "Inventory" tab) | P5: Ability Cards | T5: Possible Perks | U5: Battle Goals | V5: Used Perks | W5: Ability Cards 1 | X5: Ability Cards 2
B6: Battle Goals | K6: Remove four +0 cards | M6: {=IFERROR(INDEX(Inventory!$B$5:$B$56,SMALL(IF($D$2=Inventory!$F$5:$F$56,ROW(Inventory!$F$5:$F$56)-4,""),1)),"")} | N6: {=IFERROR(INDEX(Inventory!$C$5:$C$56,SMALL(IF($D$2=Inventory!$F$5:$F$56,ROW(Inventory!$F$5:$F$56)-4,""),1)),"")} | T6: =ROUNDDOWN(COUNTIF(U6:U23,TRUE)/3,0)+COUNTIF(Campaign!L12,TRUE)+S3-1-COUNTIF(V6:V20,TRUE) -> 0 | U6: FALSE | V6: FALSE
K7: Remove two -1 cards | M7: {=IFERROR(INDEX(Inventory!$B$5:$B$56,SMALL(IF($D$2=Inventory!$F$5:$F$56,ROW(Inventory!$F$5:$F$56)-4,""),2)),"")} | N7: {=IFERROR(INDEX(Inventory!$C$5:$C$56,SMALL(IF($D$2=Inventory!$F$5:$F$56,ROW(Inventory!$F$5:$F$56)-4,""),2)),"")} | U7: FALSE | V7: FALSE
K8: Remove two -1 cards | M8: {=IFERROR(INDEX(Inventory!$B$5:$B$56,SMALL(IF($D$2=Inventory!$F$5:$F$56,ROW(Inventory!$F$5:$F$56)-4,""),3)),"")} | N8: {=IFERROR(INDEX(Inventory!$C$5:$C$56,SMALL(IF($D$2=Inventory!$F$5:$F$56,ROW(Inventory!$F$5:$F$56)-4,""),3)),"")} | U8: FALSE | V8: FALSE
K9: Remove one -2 card and one +1 card | M9: {=IFERROR(INDEX(Inventory!$B$5:$B$56,SMALL(IF($D$2=Inventory!$F$5:$F$56,ROW(Inventory!$F$5:$F$56)-4,""),4)),"")} | N9: {=IFERROR(INDEX(Inventory!$C$5:$C$56,SMALL(IF($D$2=Inventory!$F$5:$F$56,ROW(Inventory!$F$5:$F$56)-4,""),4)),"")} | U9: FALSE | V9: FALSE
B10: Modifier Deck | K10: Replace one +0 card with one +2 MUDDLE card | M10: {=IFERROR(INDEX(Inventory!$B$5:$B$56,SMALL(IF($D$2=Inventory!$F$5:$F$56,ROW(Inventory!$F$5:$F$56)-4,""),5)),"")} | N10: {=IFERROR(INDEX(Inventory!$C$5:$C$56,SMALL(IF($D$2=Inventory!$F$5:$F$56,ROW(Inventory!$F$5:$F$56)-4,""),5)),"")} | U10: FALSE | V10: FALSE
B11: (2x): 1 | F11: NULL: 1 | K11: Replace one +0 card with one +2 MUDDLE card | M11: {=IFERROR(INDEX(Inventory!$B$5:$B$56,SMALL(IF($D$2=Inventory!$F$5:$F$56,ROW(Inventory!$F$5:$F$56)-4,""),6)),"")} | N11: {=IFERROR(INDEX(Inventory!$C$5:$C$56,SMALL(IF($D$2=Inventory!$F$5:$F$56,ROW(Inventory!$F$5:$F$56)-4,""),6)),"")} | U11: FALSE | V11: FALSE
B12: ="(+2): "&1+V13+V14 -> (+2): 1 | F12: ="(-2): "&1-V9 -> (-2): 1 | K12: Replace one -1 card with one +0 POISON card | M12: {=IFERROR(INDEX(Inventory!$B$5:$B$56,SMALL(IF($D$2=Inventory!$F$5:$F$56,ROW(Inventory!$F$5:$F$56)-4,""),7)),"")} | N12: {=IFERROR(INDEX(Inventory!$C$5:$C$56,SMALL(IF($D$2=Inventory!$F$5:$F$56,ROW(Inventory!$F$5:$F$56)-4,""),7)),"")} | U12: FALSE | V12: FALSE
B13: ="(+1): "&5-V9-V15-V16-V17-V18 -> (+1): 5 | F13: ="(-1): "&5-(2*V7)-(2*V8)-V12 -> (-1): 5 | K13: Add one +2 card | M13: {=IFERROR(INDEX(Inventory!$B$5:$B$56,SMALL(IF($D$2=Inventory!$F$5:$F$56,ROW(Inventory!$F$5:$F$56)-4,""),8)),"")} | N13: {=IFERROR(INDEX(Inventory!$C$5:$C$56,SMALL(IF($D$2=Inventory!$F$5:$F$56,ROW(Inventory!$F$5:$F$56)-4,""),8)),"")} | U13: FALSE | V13: FALSE
B14: ="(+2) EARTH: "&0+V15+V16 -> (+2) EARTH: 0 | F14: ="(+0): "&6-(4*V6)-V10-V11 -> (+0): 6 | K14: Add one +2 card | M14: {=IFERROR(INDEX(Inventory!$B$5:$B$56,SMALL(IF($D$2=Inventory!$F$5:$F$56,ROW(Inventory!$F$5:$F$56)-4,""),9)),"")} | N14: {=IFERROR(INDEX(Inventory!$C$5:$C$56,SMALL(IF($D$2=Inventory!$F$5:$F$56,ROW(Inventory!$F$5:$F$56)-4,""),9)),"")} | U14: FALSE | V14: FALSE
B15: ="(+2) FIRE: "&0+V17+V18 -> (+2) FIRE: 0 | K15: Replace one +1 card with one +2 EARTH card | M15: {=IFERROR(INDEX(Inventory!$B$5:$B$56,SMALL(IF($D$2=Inventory!$F$5:$F$56,ROW(Inventory!$F$5:$F$56)-4,""),10)),"")} | N15: {=IFERROR(INDEX(Inventory!$C$5:$C$56,SMALL(IF($D$2=Inventory!$F$5:$F$56,ROW(Inventory!$F$5:$F$56)-4,""),10)),"")} | U15: FALSE | V15: FALSE
B16: ="(+2) MUDDLE: "&0+V10+V11 -> (+2) MUDDLE: 0 | K16: Replace one +1 card with one +2 EARTH card | M16: {=IFERROR(INDEX(Inventory!$B$5:$B$56,SMALL(IF($D$2=Inventory!$F$5:$F$56,ROW(Inventory!$F$5:$F$56)-4,""),11)),"")} | N16: {=IFERROR(INDEX(Inventory!$C$5:$C$56,SMALL(IF($D$2=Inventory!$F$5:$F$56,ROW(Inventory!$F$5:$F$56)-4,""),11)),"")} | U16: FALSE | V16: FALSE
B17: ="(+0) POISON: "&0+V12 -> (+0) POISON: 0 | K17: Replace one +1 card with one +2 FIRE card | M17: {=IFERROR(INDEX(Inventory!$B$5:$B$56,SMALL(IF($D$2=Inventory!$F$5:$F$56,ROW(Inventory!$F$5:$F$56)-4,""),12)),"")} | N17: {=IFERROR(INDEX(Inventory!$C$5:$C$56,SMALL(IF($D$2=Inventory!$F$5:$F$56,ROW(Inventory!$F$5:$F$56)-4,""),12)),"")} | U17: FALSE | V17: FALSE
B18: ="(+0) All adjacent enemies suffer 1 damage: "&0+V19+V20 -> (+0) All adjacent enemies suffer 1 damage: 0 | K18: Replace one +1 card with one +2 FIRE card | M18: {=IFERROR(INDEX(Inventory!$B$5:$B$56,SMALL(IF($D$2=Inventory!$F$5:$F$56,ROW(Inventory!$F$5:$F$56)-4,""),13)),"")} | N18: {=IFERROR(INDEX(Inventory!$C$5:$C$56,SMALL(IF($D$2=Inventory!$F$5:$F$56,ROW(Inventory!$F$5:$F$56)-4,""),13)),"")} | U18: FALSE | V18: FALSE
K19: Add one +0 All adjacent enemies suffer 1 damage card | M19: {=IFERROR(INDEX(Inventory!$B$5:$B$56,SMALL(IF($D$2=Inventory!$F$5:$F$56,ROW(Inventory!$F$5:$F$56)-4,""),14)),"")} | N19: {=IFERROR(INDEX(Inventory!$C$5:$C$56,SMALL(IF($D$2=Inventory!$F$5:$F$56,ROW(Inventory!$F$5:$F$56)-4,""),14)),"")} | U19: FALSE | V19: FALSE
B20: ="TOTAL CARDS: "&20-(4*V6)-(2*V7)-(2*V8)-(2*V9)+V13+V14+V19+V20 -> TOTAL CARDS: 20 | K20: Add one +0 All adjacent enemies suffer 1 damage card | M20: {=IFERROR(INDEX(Inventory!$B$5:$B$56,SMALL(IF($D$2=Inventory!$F$5:$F$56,ROW(Inventory!$F$5:$F$56)-4,""),15)),"")} | N20: {=IFERROR(INDEX(Inventory!$C$5:$C$56,SMALL(IF($D$2=Inventory!$F$5:$F$56,ROW(Inventory!$F$5:$F$56)-4,""),15)),"")} | U20: FALSE | V20: FALSE
U21: FALSE
U22: FALSE
U23: FALSE

Sheet Hatchet
D2: <NAME>
D3: Inox Hatchet | Q3: Level | S3: =IF(D5>=500,9,IF(D5>=420,8,IF(D5>=345,7,IF(D5>=275,6,IF(D5>=210,5,IF(D5>=150,4,IF(D5>=95,3,IF(D5>=45,2,1)))))))) -> 1
B5: XP | F5: Gold | J5: ="Available Perks: "&T6 -> Available Perks: 0 | M5: Inventory (see "Inventory" tab) | P5: Ability Cards | T5: Possible Perks | U5: Battle Goals | V5: Used Perks | W5: Ability Cards 1 | X5: Ability Cards 2
B6: Battle Goals | K6: Remove two -1 cards | M6: {=IFERROR(INDEX(Inventory!$B$5:$B$56,SMALL(IF($D$2=Inventory!$F$5:$F$56,ROW(Inventory!$F$5:$F$56)-4,""),1)),"")} | N6: {=IFERROR(INDEX(Inventory!$C$5:$C$56,SMALL(IF($D$2=Inventory!$F$5:$F$56,ROW(Inventory!$F$5:$F$56)-4,""),1)),"")} | T6: =ROUNDDOWN(COUNTIF(U6:U23,TRUE)/3,0)+COUNTIF(Campaign!L12,TRUE)+S3-1-COUNTIF(V6:V20,TRUE) -> 0 | U6: FALSE | V6: FALSE
K7: Remove two -1 cards | M7: {=IFERROR(INDEX(Inventory!$B$5:$B$56,SMALL(IF($D$2=Inventory!$F$5:$F$56,ROW(Inventory!$F$5:$F$56)-4,""),2)),"")} | N7: {=IFERROR(INDEX(Inventory!$C$5:$C$56,SMALL(IF($D$2=Inventory!$F$5:$F$56,ROW(Inventory!$F$5:$F$56)-4,""),2)),"")} | U7: FALSE | V7: FALSE
K8: Replace one +0 card with one +2 MUDDLE card | M8: {=IFERROR(INDEX(Inventory!$B$5:$B$56,SMALL(IF($D$2=Inventory!$F$5:$F$56,ROW(Inventory!$F$5:$F$56)-4,""),3)),"")} | N8: {=IFERROR(INDEX(Inventory!$C$5:$C$56,SMALL(IF($D$2=Inventory!$F$5:$F$56,ROW(Inventory!$F$5:$F$56)-4,""),3)),"")} | U8: FALSE | V8: FALSE
K9: Replace one +0 card with one +1 POISON card | M9: {=IFERROR(INDEX(Inventory!$B$5:$B$56,SMALL(IF($D$2=Inventory!$F$5:$F$56,ROW(Inventory!$F$5:$F$56)-4,""),4)),"")} | N9: {=IFERROR(INDEX(Inventory!$C$5:$C$56,SMALL(IF($D$2=Inventory!$F$5:$F$56,ROW(Inventory!$F$5:$F$56)-4,""),4)),"")} | U9: FALSE | V9: FALSE
B10: Modifier Deck | K10: Replace one +0 card with one +1 WOUND card | M10: {=IFERROR(INDEX(Inventory!$B$5:$B$56,SMALL(IF($D$2=Inventory!$F$5:$F$56,ROW(Inventory!$F$5:$F$56)-4,""),5)),"")} | N10: {=IFERROR(INDEX(Inventory!$C$5:$C$56,SMALL(IF($D$2=Inventory!$F$5:$F$56,ROW(Inventory!$F$5:$F$56)-4,""),5)),"")} | U10: FALSE | V10: FALSE
B11: (2x): 1 | F11: NULL: 1 | K11: Replace one +0 card with one +1 IMMOBILIZE card | M11: {=IFERROR(INDEX(Inventory!$B$5:$B$56,SMALL(IF($D$2=Inventory!$F$5:$F$56,ROW(Inventory!$F$5:$F$56)-4,""),6)),"")} | N11: {=IFERROR(INDEX(Inventory!$C$5:$C$56,SMALL(IF($D$2=Inventory!$F$5:$F$56,ROW(Inventory!$F$5:$F$56)-4,""),6)),"")} | U11: FALSE | V11: FALSE
B12: (+2): 1 | F12: (-2): 1 | K12: Replace one +0 card with one +1 PUSH 2 card | M12: {=IFERROR(INDEX(Inventory!$B$5:$B$56,SMALL(IF($D$2=Inventory!$F$5:$F$56,ROW(Inventory!$F$5:$F$56)-4,""),7)),"")} | N12: {=IFERROR(INDEX(Inventory!$C$5:$C$56,SMALL(IF($D$2=Inventory!$F$5:$F$56,ROW(Inventory!$F$5:$F$56)-4,""),7)),"")} | U12: FALSE | V12: FALSE
B13: ="(+1): "&5-V14-V18-V19-V20 -> (+1): 5 | F13: ="(-1): "&5-(2*V6)-(2*V7) -> (-1): 5 | K13: Replace one +0 card with one +0 STUN card | M13: {=IFERROR(INDEX(Inventory!$B$5:$B$56,SMALL(IF($D$2=Inventory!$F$5:$F$56,ROW(Inventory!$F$5:$F$56)-4,""),8)),"")} | N13: {=IFERROR(INDEX(Inventory!$C$5:$C$56,SMALL(IF($D$2=Inventory!$F$5:$F$56,ROW(Inventory!$F$5:$F$56)-4,""),8)),"")} | U13: FALSE | V13: FALSE
B14: ="(+3): "&0+V18+V19+V20 -> (+3): 0 | F14: ="(+0): "&6-V8-V9-V10-V11-V12-V13 -> (+0): 6 | K14: Replace one +1 card with one +1 STUN card | M14: {=IFERROR(INDEX(Inventory!$B$5:$B$56,SMALL(IF($D$2=Inventory!$F$5:$F$56,ROW(Inventory!$F$5:$F$56)-4,""),9)),"")} | N14: {=IFERROR(INDEX(Inventory!$C$5:$C$56,SMALL(IF($D$2=Inventory!$F$5:$F$56,ROW(Inventory!$F$5:$F$56)-4,""),9)),"")} | U14: FALSE | V14: FALSE
B15: ="(+1) PUSH 2: "&0+V12 -> (+1) PUSH 2: 0 | F15: ="(+2) WIND: "&0+V15+V16+V17 -> (+2) WIND: 0 | K15: Add one +2 WIND card | M15: {=IFERROR(INDEX(Inventory!$B$5:$B$56,SMALL(IF($D$2=Inventory!$F$5:$F$56,ROW(Inventory!$F$5:$F$56)-4,""),10)),"")} | N15: {=IFERROR(INDEX(Inventory!$C$5:$C$56,SMALL(IF($D$2=Inventory!$F$5:$F$56,ROW(Inventory!$F$5:$F$56)-4,""),10)),"")} | U15: FALSE | V15: FALSE
B16: ="(+0) STUN: "&0+V13 -> (+0) STUN: 0 | F16: ="(+1) STUN: "&0+V14 -> (+1) STUN: 0 | K16: Add one +2 WIND card | M16: {=IFERROR(INDEX(Inventory!$B$5:$B$56,SMALL(IF($D$2=Inventory!$F$5:$F$56,ROW(Inventory!$F$5:$F$56)-4,""),11)),"")} | N16: {=IFERROR(INDEX(Inventory!$C$5:$C$56,SMALL(IF($D$2=Inventory!$F$5:$F$56,ROW(Inventory!$F$5:$F$56)-4,""),11)),"")} | U16: FALSE | V16: FALSE
B17: ="(+1) WOUND: "&0+V10 -> (+1) WOUND: 0 | F17: ="(+1) POISN: "&0+V9 -> (+1) POISN: 0 | K17: Add one +2 WIND card | M17: {=IFERROR(INDEX(Inventory!$B$5:$B$56,SMALL(IF($D$2=Inventory!$F$5:$F$56,ROW(Inventory!$F$5:$F$56)-4,""),12)),"")} | N17: {=IFERROR(INDEX(Inventory!$C$5:$C$56,SMALL(IF($D$2=Inventory!$F$5:$F$56,ROW(Inventory!$F$5:$F$56)-4,""),12)),"")} | U17: FALSE | V17: FALSE
B18: ="(+2) MUDDLE: "&0+V8 -> (+2) MUDDLE: 0 | K18: Replace one +1 card with one +3 card | M18: {=IFERROR(INDEX(Inventory!$B$5:$B$56,SMALL(IF($D$2=Inventory!$F$5:$F$56,ROW(Inventory!$F$5:$F$56)-4,""),13)),"")} | N18: {=IFERROR(INDEX(Inventory!$C$5:$C$56,SMALL(IF($D$2=Inventory!$F$5:$F$56,ROW(Inventory!$F$5:$F$56)-4,""),13)),"")} | U18: FALSE | V18: FALSE
B19: ="(+1) IMMOBILIZE: "&0+V11 -> (+1) IMMOBILIZE: 0 | K19: Replace one +1 card with one +3 card | M19: {=IFERROR(INDEX(Inventory!$B$5:$B$56,SMALL(IF($D$2=Inventory!$F$5:$F$56,ROW(Inventory!$F$5:$F$56)-4,""),14)),"")} | N19: {=IFERROR(INDEX(Inventory!$C$5:$C$56,SMALL(IF($D$2=Inventory!$F$5:$F$56,ROW(Inventory!$F$5:$F$56)-4,""),14)),"")} | U19: FALSE | V19: FALSE
B20: ="TOTAL CARDS: "&20-(2*V6)-(2*V7)+V15+V16+V17 -> TOTAL CARDS: 20 | K20: Replace one +1 card with one +3 card | M20: {=IFERROR(INDEX(Inventory!$B$5:$B$56,SMALL(IF($D$2=Inventory!$F$5:$F$56,ROW(Inventory!$F$5:$F$56)-4,""),15)),"")} | N20: {=IFERROR(INDEX(Inventory!$C$5:$C$56,SMALL(IF($D$2=Inventory!$F$5:$F$56,ROW(Inventory!$F$5:$F$56)-4,""),15)),"")} | U20: FALSE | V20: FALSE
U21: FALSE
U22: FALSE
U23: FALSE

Sheet Red Guard
D2: <NAME>
D3: Valrath Red Guard | Q3: Level | S3: =IF(D5>=500,9,IF(D5>=420,8,IF(D5>=345,7,IF(D5>=275,6,IF(D5>=210,5,IF(D5>=150,4,IF(D5>=95,3,IF(D5>=45,2,1)))))))) -> 1
B5: XP | F5: Gold | J5: ="Available Perks: "&T6 -> Available Perks: 0 | M5: Inventory (see "Inventory" tab) | P5: Ability Cards | T5: Possible Perks | U5: Battle Goals | V5: Used Perks | W5: Ability Cards 1 | X5: Ability Cards 2
B6: Battle Goals | K6: Remove four +0 cards | M6: {=IFERROR(INDEX(Inventory!$B$5:$B$56,SMALL(IF($D$2=Inventory!$F$5:$F$56,ROW(Inventory!$F$5:$F$56)-4,""),1)),"")} | N6: {=IFERROR(INDEX(Inventory!$C$5:$C$56,SMALL(IF($D$2=Inventory!$F$5:$F$56,ROW(Inventory!$F$5:$F$56)-4,""),1)),"")} | T6: =ROUNDDOWN(COUNTIF(U6:U23,TRUE)/3,0)+COUNTIF(Campaign!L12,TRUE)+S3-1-COUNTIF(V6:V20,TRUE) -> 0 | U6: FALSE | V6: FALSE
K7: Remove two -1 cards | M7: {=IFERROR(INDEX(Inventory!$B$5:$B$56,SMALL(IF($D$2=Inventory!$F$5:$F$56,ROW(Inventory!$F$5:$F$56)-4,""),2)),"")} | N7: {=IFERROR(INDEX(Inventory!$C$5:$C$56,SMALL(IF($D$2=Inventory!$F$5:$F$56,ROW(Inventory!$F$5:$F$56)-4,""),2)),"")} | U7: FALSE | V7: FALSE
K8: Remove one -2 card and one +1 card | M8: {=IFERROR(INDEX(Inventory!$B$5:$B$56,SMALL(IF($D$2=Inventory!$F$5:$F$56,ROW(Inventory!$F$5:$F$56)-4,""),3)),"")} | N8: {=IFERROR(INDEX(Inventory!$C$5:$C$56,SMALL(IF($D$2=Inventory!$F$5:$F$56,ROW(Inventory!$F$5:$F$56)-4,""),3)),"")} | U8: FALSE | V8: FALSE
K9: Replace one -1 card with one +1 card | M9: {=IFERROR(INDEX(Inventory!$B$5:$B$56,SMALL(IF($D$2=Inventory!$F$5:$F$56,ROW(Inventory!$F$5:$F$56)-4,""),4)),"")} | N9: {=IFERROR(INDEX(Inventory!$C$5:$C$56,SMALL(IF($D$2=Inventory!$F$5:$F$56,ROW(Inventory!$F$5:$F$56)-4,""),4)),"")} | U9: FALSE | V9: FALSE
B10: Modifier Deck | K10: Replace one -1 card with one +1 card | M10: {=IFERROR(INDEX(Inventory!$B$5:$B$56,SMALL(IF($D$2=Inventory!$F$5:$F$56,ROW(Inventory!$F$5:$F$56)-4,""),5)),"")} | N10: {=IFERROR(INDEX(Inventory!$C$5:$C$56,SMALL(IF($D$2=Inventory!$F$5:$F$56,ROW(Inventory!$F$5:$F$56)-4,""),5)),"")} | U10: FALSE | V10: FALSE
B11: (2x): 1 | F11: NULL: 1 | K11: Replace one +1 card with one +2 FIRE card | M11: {=IFERROR(INDEX(Inventory!$B$5:$B$56,SMALL(IF($D$2=Inventory!$F$5:$F$56,ROW(Inventory!$F$5:$F$56)-4,""),6)),"")} | N11: {=IFERROR(INDEX(Inventory!$C$5:$C$56,SMALL(IF($D$2=Inventory!$F$5:$F$56,ROW(Inventory!$F$5:$F$56)-4,""),6)),"")} | U11: FALSE | V11: FALSE
B12: (+2): 1 | F12: ="(-2): "&1-V8 -> (-2): 1 | K12: Replace one +1 card with one +2 FIRE card | M12: {=IFERROR(INDEX(Inventory!$B$5:$B$56,SMALL(IF($D$2=Inventory!$F$5:$F$56,ROW(Inventory!$F$5:$F$56)-4,""),7)),"")} | N12: {=IFERROR(INDEX(Inventory!$C$5:$C$56,SMALL(IF($D$2=Inventory!$F$5:$F$56,ROW(Inventory!$F$5:$F$56)-4,""),7)),"")} | U12: FALSE | V12: FALSE
B13: ="(+1): "&5-V8+V9+V10-V11-V12-V13-V14 -> (+1): 5 | F13: ="(-1): "&5-(2*V7)-V9-V10 -> (-1): 5 | K13: Replace one +1 card with one +2 LIGHT card | M13: {=IFERROR(INDEX(Inventory!$B$5:$B$56,SMALL(IF($D$2=Inventory!$F$5:$F$56,ROW(Inventory!$F$5:$F$56)-4,""),8)),"")} | N13: {=IFERROR(INDEX(Inventory!$C$5:$C$56,SMALL(IF($D$2=Inventory!$F$5:$F$56,ROW(Inventory!$F$5:$F$56)-4,""),8)),"")} | U13: FALSE | V13: FALSE
B14: ="(+2) FIRE: "&0+V11+V12 -> (+2) FIRE: 0 | F14: ="(+0): "&6-(4*V6)-V19-V20 -> (+0): 6 | K14: Replace one +1 card with one +2 LIGHT card | M14: {=IFERROR(INDEX(Inventory!$B$5:$B$56,SMALL(IF($D$2=Inventory!$F$5:$F$56,ROW(Inventory!$F$5:$F$56)-4,""),9)),"")} | N14: {=IFERROR(INDEX(Inventory!$C$5:$C$56,SMALL(IF($D$2=Inventory!$F$5:$F$56,ROW(Inventory!$F$5:$F$56)-4,""),9)),"")} | U14: FALSE | V14: FALSE
B15: ="(+2) LIGHT: "&0+V13+V14 -> (+2) LIGHT: 0 | K15: Add one +1 FIRE & LIGHT card | M15: {=IFERROR(INDEX(Inventory!$B$5:$B$56,SMALL(IF($D$2=Inventory!$F$5:$F$56,ROW(Inventory!$F$5:$F$56)-4,""),10)),"")} | N15: {=IFERROR(INDEX(Inventory!$C$5:$C$56,SMALL(IF($D$2=Inventory!$F$5:$F$56,ROW(Inventory!$F$5:$F$56)-4,""),10)),"")} | U15: FALSE | V15: FALSE
B16: ="(+1) FIRE & LIGHT: "&0+V15+V16 -> (+1) FIRE & LIGHT: 0 | K16: Add one +1 FIRE & LIGHT card | M16: {=IFERROR(INDEX(Inventory!$B$5:$B$56,SMALL(IF($D$2=Inventory!$F$5:$F$56,ROW(Inventory!$F$5:$F$56)-4,""),11)),"")} | N16: {=IFERROR(INDEX(Inventory!$C$5:$C$56,SMALL(IF($D$2=Inventory!$F$5:$F$56,ROW(Inventory!$F$5:$F$56)-4,""),11)),"")} | U16: FALSE | V16: FALSE
B17: ="(+1) SHIELD 1: "&0+V17+V18 -> (+1) SHIELD 1: 0 | K17: Add one +1 SHIELD 1 card | M17: {=IFERROR(INDEX(Inventory!$B$5:$B$56,SMALL(IF($D$2=Inventory!$F$5:$F$56,ROW(Inventory!$F$5:$F$56)-4,""),12)),"")} | N17: {=IFERROR(INDEX(Inventory!$C$5:$C$56,SMALL(IF($D$2=Inventory!$F$5:$F$56,ROW(Inventory!$F$5:$F$56)-4,""),12)),"")} | U17: FALSE | V17: FALSE
B18: ="(+1) IMMOBILIZE: "&0+V19 -> (+1) IMMOBILIZE: 0 | K18: Add one +1 SHIELD 1 card | M18: {=IFERROR(INDEX(Inventory!$B$5:$B$56,SMALL(IF($D$2=Inventory!$F$5:$F$56,ROW(Inventory!$F$5:$F$56)-4,""),13)),"")} | N18: {=IFERROR(INDEX(Inventory!$C$5:$C$56,SMALL(IF($D$2=Inventory!$F$5:$F$56,ROW(Inventory!$F$5:$F$56)-4,""),13)),"")} | U18: FALSE | V18: FALSE
B19: ="(+1) WOUND: "&0+V20 -> (+1) WOUND: 0 | K19: Replace one +0 card with one +1 IMMOBILIZE card | M19: {=IFERROR(INDEX(Inventory!$B$5:$B$56,SMALL(IF($D$2=Inventory!$F$5:$F$56,ROW(Inventory!$F$5:$F$56)-4,""),14)),"")} | N19: {=IFERROR(INDEX(Inventory!$C$5:$C$56,SMALL(IF($D$2=Inventory!$F$5:$F$56,ROW(Inventory!$F$5:$F$56)-4,""),14)),"")} | U19: FALSE | V19: FALSE
B20: ="TOTAL CARDS: "&20-(4*V6)-(2*V7)-(2*V8)+V15+V16+V17+V18 -> TOTAL CARDS: 20 | K20: Replace one +0 card with one +1 WOUND card | M20: {=IFERROR(INDEX(Inventory!$B$5:$B$56,SMALL(IF($D$2=Inventory!$F$5:$F$56,ROW(Inventory!$F$5:$F$56)-4,""),15)),"")} | N20: {=IFERROR(INDEX(Inventory!$C$5:$C$56,SMALL(IF($D$2=Inventory!$F$5:$F$56,ROW(Inventory!$F$5:$F$56)-4,""),15)),"")} | U20: FALSE | V20: FALSE
U21: FALSE
U22: FALSE
U23: FALSE

Sheet Inventory
B2: Inventory
B4: ID | C4: Name | D4: Type | E4: Cost | F4: Owner | H4: ID | I4: Name | J4: Type | K4: Cost | L4: Owner | M4: Owner List | N4: Filtered Owner List
B5: =IF(Campaign!$Y$4,1,"") | C5: =IF(Campaign!$Y$4,"Eagle-Eye Goggles","") | D5: =IF(Campaign!$Y$4,"Head","") | E5: =IF(Campaign!$Y$4,30,"") | H5: =IF(Campaign!$O$13,14,"") | I5: =IF(Campaign!$O$13,"Mana Potion","") | J5: =IF(Campaign!$O$13,"Small Item","") | K5: =IF(Campaign!$O$13,10,"")
B6: =IF(Campaign!$Y$4,1,"") | C6: =IF(Campaign!$Y$4,"Eagle-Eye Goggles","") | D6: =IF(Campaign!$Y$4,"Head","") | E6: =IF(Campaign!$Y$4,30,"") | H6: =IF(Campaign!$L$13,14,"") | I6: =IF(Campaign!$L$13,"Mana Potion","") | J6: =IF(Campaign!$L$13,"Small Item","") | K6: =IF(Campaign!$L$13,10,"") | M6: =IF(NOT(OR(ISBLANK(Voidwarden!$D$2),Voidwarden!$D$2="<NAME>")),Voidwarden!$D$2,"") | N6: {=IFERROR(INDEX($M$6:$M$9,SMALL(IF(""<>$M$6:$M$9,ROW($M$6:$M$9)-5,""),1)),"")}
B7: =IF(Campaign!$Y$4,2,"") | C7: =IF(Campaign!$Y$4,"Iron Helmet","") | D7: =IF(Campaign!$Y$4,"Head","") | E7: =IF(Campaign!$Y$4,20,"") | H7: =IF(Campaign!$Y$5,15,"") | I7: =IF(Campaign!$Y$5,"Amulet of Life","") | J7: =IF(Campaign!$Y$5,"Head","") | K7: =IF(Campaign!$Y$5,20,"") | M7: =IF(NOT(OR(ISBLANK(Demolitionist!$D$2),Demolitionist!$D$2="<NAME>")),Demolitionist!$D$2,"") | N7: {=IFERROR(INDEX($M$6:$M$9,SMALL(IF(""<>$M$6:$M$9,ROW($M$6:$M$9)-5,""),2)),"")}
B8: =IF(Campaign!$Y$4,2,"") | C8: =IF(Campaign!$Y$4,"Iron Helmet","") | D8: =IF(Campaign!$Y$4,"Head","") | E8: =IF(Campaign!$Y$4,20,"") | H8: =IF(Campaign!$Y$5,16,"") | I8: =IF(Campaign!$Y$5,"Robes of Evocation","") | J8: =IF(Campaign!$Y$5,"Body","") | K8: =IF(Campaign!$Y$5,40,"") | M8: =IF(NOT(OR(ISBLANK(Hatchet!$D$2),Hatchet!$D$2="<NAME>")),Hatchet!$D$2,"") | N8: {=IFERROR(INDEX($M$6:$M$9,SMALL(IF(""<>$M$6:$M$9,ROW($M$6:$M$9)-5,""),3)),"")}
B9: =IF(Campaign!$Y$4,3,"") | C9: =IF(Campaign!$Y$4,"Chain Armor","") | D9: =IF(Campaign!$Y$4,"Body","") | E9: =IF(Campaign!$Y$4,30,"") | H9: =IF(Campaign!$Y$5,17,"") | I9: =IF(Campaign!$Y$5,"Comfortable Shoes","") | J9: =IF(Campaign!$Y$5,"Feet","") | K9: =IF(Campaign!$Y$5,30,"") | M9: =IF(NOT(OR(ISBLANK('Red Guard'!$D$2),'Red Guard'!$D$2="<NAME>")),'Red Guard'!$D$2,"") | N9: {=IFERROR(INDEX($M$6:$M$9,SMALL(IF(""<>$M$6:$M$9,ROW($M$6:$M$9)-5,""),4)),"")}
B10: =IF(Campaign!$Y$4,3,"") | C10: =IF(Campaign!$Y$4,"Chain Armor","") | D10: =IF(Campaign!$Y$4,"Body","") | E10: =IF(Campaign!$Y$4,30,"") | H10: =IF(Campaign!$Y$5,18,"") | I10: =IF(Campaign!$Y$5,"Battle-Axe","") | J10: =IF(Campaign!$Y$5,"Hand","") | K10: =IF(Campaign!$Y$5,25,"")
B11: =IF(Campaign!$Y$4,4,"") | C11: =IF(Campaign!$Y$4,"Studded Leather","") | D11: =IF(Campaign!$Y$4,"Body","") | E11: =IF(Campaign!$Y$4,25,"") | H11: =IF(Campaign!$Y$5,19,"") | I11: =IF(Campaign!$Y$5,"Black Candle","") | J11: =IF(Campaign!$Y$5,"Hand","") | K11: =IF(Campaign!$Y$5,40,"") | N11: =4-COUNTIF($N$6:$N$9,"") -> 0
B12: =IF(Campaign!$Y$4,4,"") | C12: =IF(Campaign!$Y$4,"Studded Leather","") | D12: =IF(Campaign!$Y$4,"Body","") | E12: =IF(Campaign!$Y$4,25,"") | H12: =IF(Campaign!$Y$5,20,"") | I12: =IF(Campaign!$Y$5,"Stun Powder","") | J12: =IF(Campaign!$Y$5,"Small Item","") | K12: =IF(Campaign!$Y$5,20,"")
B13: =IF(Campaign!$Y$4,5,"") | C13: =IF(Campaign!$Y$4,"Weathered Boots","") | D13: =IF(Campaign!$Y$4,"Feet","") | E13: =IF(Campaign!$Y$4,15,"") | H13: =IF(Campaign!$Y$5,20,"") | I13: =IF(Campaign!$Y$5,"Stun Powder","") | J13: =IF(Campaign!$Y$5,"Small Item","") | K13: =IF(Campaign!$Y$5,20,"")
B14: =IF(Campaign!$Y$4,5,"") | C14: =IF(Campaign!$Y$4,"Weathered Boots","") | D14: =IF(Campaign!$Y$4,"Feet","") | E14: =IF(Campaign!$Y$4,15,"") | H14: =IF(Campaign!$Y$6,21,"") | I14: =IF(Campaign!$Y$6,"Hawk Helm","") | J14: =IF(Campaign!$Y$6,"Head","") | K14: =IF(Campaign!$Y$6,20,"")
B15: =IF(Campaign!$Y$4,6,"") | C15: =IF(Campaign!$Y$4,"Winged Shoes","") | D15: =IF(Campaign!$Y$4,"Feet","") | E15: =IF(Campaign!$Y$4,15,"") | H15: =IF(Campaign!$Y$6,22,"") | I15: =IF(Campaign!$Y$6,"Bladed Armor","") | J15: =IF(Campaign!$Y$6,"Body","") | K15: =IF(Campaign!$Y$6,45,"")
B16: =IF(Campaign!$Y$4,6,"") | C16: =IF(Campaign!$Y$4,"Winged Shoes","") | D16: =IF(Campaign!$Y$4,"Feet","") | E16: =IF(Campaign!$Y$4,15,"") | H16: =IF(Campaign!$Y$6,23,"") | I16: =IF(Campaign!$Y$6,"Boots of Striding","") | J16: =IF(Campaign!$Y$6,"Feet","") | K16: =IF(Campaign!$Y$6,30,"")
B17: =IF(Campaign!$Y$4,7,"") | C17: =IF(Campaign!$Y$4,"Heater Shield","") | D17: =IF(Campaign!$Y$4,"Hand","") | E17: =IF(Campaign!$Y$4,20,"") | H17: =IF(Campaign!$Y$6,24,"") | I17: =IF(Campaign!$Y$6,"Volatile Bomb","") | J17: =IF(Campaign!$Y$6,"Hand","") | K17: =IF(Campaign!$Y$6,40,"")
B18: =IF(Campaign!$Y$4,7,"") | C18: =IF(Campaign!$Y$4,"Heater Shield","") | D18: =IF(Campaign!$Y$4,"Hand","") | E18: =IF(Campaign!$Y$4,20,"") | H18: =IF(Campaign!$Y$6,25,"") | I18: =IF(Campaign!$Y$6,"Barbed Chain","") | J18: =IF(Campaign!$Y$6,"Hand","") | K18: =IF(Campaign!$Y$6,30,"")
B19: =IF(Campaign!$Y$4,8,"") | C19: =IF(Campaign!$Y$4,"Throwing Hammer","") | D19: =IF(Campaign!$Y$4,"Hand","") | E19: =IF(Campaign!$Y$4,30,"") | H19: =IF(OR(Campaign!$Y$6,Campaign!$Y$16),26,"") | I19: =IF(OR(Campaign!$Y$6,Campaign!$Y$16),"Oak Charm","") | J19: =IF(OR(Campaign!$Y$6,Campaign!$Y$16),"Small Item","") | K19: =IF(OR(Campaign!$Y$6,Campaign!$Y$16),30,"")
B20: =IF(Campaign!$Y$4,8,"") | C20: =IF(Campaign!$Y$4,"Throwing Hammer","") | D20: =IF(Campaign!$Y$4,"Hand","") | E20: =IF(Campaign!$Y$4,30,"") | H20: =IF(Campaign!$Y$6,26,"") | I20: =IF(Campaign!$Y$6,"Oak Charm","") | J20: =IF(Campaign!$Y$6,"Small Item","") | K20: =IF(Campaign!$Y$6,30,"")
B21: =IF(Campaign!$Y$4,9,"") | C21: =IF(Campaign!$Y$4,"Poison Dagger","") | D21: =IF(Campaign!$Y$4,"Hand","") | E21: =IF(Campaign!$Y$4,20,"") | H21: =IF(Campaign!$Y$8,27,"") | I21: =IF(Campaign!$Y$8,"Fateful Compass","") | J21: =IF(Campaign!$Y$8,"Small Item","") | K21: =IF(Campaign!$Y$8,25,"")
B22: =IF(Campaign!$Y$4,9,"") | C22: =IF(Campaign!$Y$4,"Poison Dagger","") | D22: =IF(Campaign!$Y$4,"Hand","") | E22: =IF(Campaign!$Y$4,20,"") | H22: =IF(Campaign!$Y$9,28,"") | I22: =IF(Campaign!$Y$9,"Flea-Bitten Shawl","") | J22: =IF(Campaign!$Y$9,"Body","") | K22: =IF(Campaign!$Y$9,10,"")
B23: =IF(Campaign!$Y$4,10,"") | C23: =IF(Campaign!$Y$4,"Iron Spear","") | D23: =IF(Campaign!$Y$4,"Hand","") | E23: =IF(Campaign!$Y$4,20,"") | H23: =IF(Campaign!$Y$10,29,"") | I23: =IF(Campaign!$Y$10,"Tower Shield","") | J23: =IF(Campaign!$Y$10,"Hand","") | K23: =IF(Campaign!$Y$10,40,"")
B24: =IF(Campaign!$Y$4,10,"") | C24: =IF(Campaign!$Y$4,"Iron Spear","") | D24: =IF(Campaign!$Y$4,"Hand","") | E24: =IF(Campaign!$Y$4,20,"") | H24: =IF(Campaign!$Z$4,30,"") | I24: =IF(Campaign!$Z$4,"Ring of Haste","") | J24: =IF(Campaign!$Z$4,"Small Item","") | K24: =IF(Campaign!$Z$4,40,"")
B25: =IF(Campaign!$Y$4,11,"") | C25: =IF(Campaign!$Y$4,"Healing Potion","") | D25: =IF(Campaign!$Y$4,"Small Item","") | E25: =IF(Campaign!$Y$4,10,"") | H25: =IF(Campaign!$Z$5,31,"") | I25: =IF(Campaign!$Z$5,"Ring of Strength","") | J25: =IF(Campaign!$Z$5,"Small Item","") | K25: =IF(Campaign!$Z$5,40,"")
B26: =IF(Campaign!$Y$4,11,"") | C26: =IF(Campaign!$Y$4,"Healing Potion","") | D26: =IF(Campaign!$Y$4,"Small Item","") | E26: =IF(Campaign!$Y$4,10,"") | H26: =IF(Campaign!$Z$6,32,"") | I26: =IF(Campaign!$Z$6,"Ring of Restoration","") | J26: =IF(Campaign!$Z$6,"Small Item","") | K26: =IF(Campaign!$Z$6,40,"")
B27: =IF(Campaign!$Y$4,12,"") | C27: =IF(Campaign!$Y$4,"Stamina Potion","") | D27: =IF(Campaign!$Y$4,"Small Item","") | E27: =IF(Campaign!$Y$4,10,"") | H27: =IF(Campaign!$Z$7,33,"") | I27: =IF(Campaign!$Z$7,"Steel Ring","") | J27: =IF(Campaign!$Z$7,"Small Item","") | K27: =IF(Campaign!$Z$7,30,"")
B28: =IF(Campaign!$Y$4,12,"") | C28: =IF(Campaign!$Y$4,"Stamina Potion","") | D28: =IF(Campaign!$Y$4,"Small Item","") | E28: =IF(Campaign!$Y$4,10,"") | H28: =IF(Campaign!$Z$8,34,"") | I28: =IF(Campaign!$Z$8,"Barbed Axe","") | J28: =IF(Campaign!$Z$8,"Hand","") | K28: =IF(Campaign!$Z$8,40,"")
B29: =IF(Campaign!$Y$4,13,"") | C29: =IF(Campaign!$Y$4,"Power Potion","") | D29: =IF(Campaign!$Y$4,"Small Item","") | E29: =IF(Campaign!$Y$4,10,"") | H29: =IF(Campaign!$Z$9,35,"") | I29: =IF(Campaign!$Z$9,"Robes of Command","") | J29: =IF(Campaign!$Z$9,"Body","") | K29: =IF(Campaign!$Z$9,40,"")
B30: =IF(Campaign!$Y$4,13,"") | C30: =IF(Campaign!$Y$4,"Power Potion","") | D30: =IF(Campaign!$Y$4,"Small Item","") | E30: =IF(Campaign!$Y$4,10,"") | H30: =IF(Campaign!$Z$10,36,"") | I30: =IF(Campaign!$Z$10,"Jet Boots","") | J30: =IF(Campaign!$Z$10,"Feet","") | K30: =IF(Campaign!$Z$10,30,"")
B31: =$H5 | C31: =$I5 | D31: =$J5 | E31: =$K5 | F31: =IF(ISBLANK($L5),"",$L5)
B32: =$H6 | C32: =$I6 | D32: =$J6 | E32: =$K6 | F32: =IF(ISBLANK($L6),"",$L6)
B33: =$H7 | C33: =$I7 | D33: =$J7 | E33: =$K7 | F33: =IF(ISBLANK($L7),"",$L7)
B34: =$H8 | C34: =$I8 | D34: =$J8 | E34: =$K8 | F34: =IF(ISBLANK($L8),"",$L8)
B35: =$H9 | C35: =$I9 | D35: =$J9 | E35: =$K9 | F35: =IF(ISBLANK($L9),"",$L9)
B36: =$H10 | C36: =$I10 | D36: =$J10 | E36: =$K10 | F36: =IF(ISBLANK($L10),"",$L10)
B37: =$H11 | C37: =$I11 | D37: =$J11 | E37: =$K11 | F37: =IF(ISBLANK($L11),"",$L11)
B38: =$H12 | C38: =$I12 | D38: =$J12 | E38: =$K12 | F38: =IF(ISBLANK($L12),"",$L12)
B39: =$H13 | C39: =$I13 | D39: =$J13 | E39: =$K13 | F39: =IF(ISBLANK($L13),"",$L13)
B40: =$H14 | C40: =$I14 | D40: =$J14 | E40: =$K14 | F40: =IF(ISBLANK($L14),"",$L14)
B41: =$H15 | C41: =$I15 | D41: =$J15 | E41: =$K15 | F41: =IF(ISBLANK($L15),"",$L15)
B42: =$H16 | C42: =$I16 | D42: =$J16 | E42: =$K16 | F42: =IF(ISBLANK($L16),"",$L16)
...

Sheet Readme
A1: Jaws of the Lion Campaign Tracker Readme
A2: Version | B2: 6
A3: Author: | B3: artoo00
A4: Last Modified: | B4: 9 October 2020
A5: Created/Modified with: | B5: Microsoft Excel 2016
A6: Attributions: | B6: Official class icons shared by Cephalofair Games (https://boardgamegeek.com/filepage/204314/class-icons) under creative commons license BY-NC-SA 4.0 (https://creativecommons.org/licenses/by-nc-sa/4.0/). Icon background colors were modified (from white) to match each class tab in this workbook. Modified icons may be used under the same license.
A7: A few instructions: | B7: On the "Campaign" tab, you don't need to type anything. Only checkboxes and radio buttons are meant to be used. Everything else is automated!
B8: Related to the line above, I have protected the worksheets to prevent the user(s) from accidentally writing over the automated portions of this file (and to protect the "spoilers" contained within). If you attempt to check a box, you may get a message about these protections. This means the box is meant to be checked by first checking its pre-requisite. For example, scenario 2 will unlock when you complete scenario 1. Thus, you should mark scenario 1 complete; then, scenario 2 will unlock automatically.
B9: Each character has their own tab. Start by entering a name for your character. This will create your party on the "Campaign" tab.
B10: Enter experience, gold, battle goal checkmarks, and ability cards.
B11: "Available Perks" is also automatically calculated. If the number is ever greater than zero, you can select a new perk for your character! "Available Perks" is not intended to ever be negative, but I don't protect against it. If it is negative, you may have added a perk before you are allowed to. Of course, I may also have calculated it incorrectly, so let me know!
B12: Character modifier decks are tracked on the character sheet. As a new perk is selected, the modifier deck automatically updates to match it.
B13: Inventory items are selected on the "Inventory" tab, and automatically appear on each character sheet.
A14: Version 2 Update: | B14: Fixed Event 17 B results.
B15: Added automated unlock of Secrets A-D.
B16: Updated scenario level and metrics for tutorial scenarios (eg. Gold conversion and bonus experience should be zero on scenario 1).
B17: Added ability card numbers to character sheets (Did not include tutorial cards).
A18: Version 3 Update: | B18: Fixed broken references to the Voidwarden's level.
A19: Version 4 Update: | B19: Added modifier deck tracking based on selected perks.
B20: Added "Inventory" tab to ease the selection of items for each character.
A21: Version 5 Update: | B21: Fixed inventory item beginning on H6 in the "Inventory" tab. Also updated reference for unlocking Item 14 in the Campaign tab.
A22: Version 6 Update: | B22: Fixed Event 1 A results.
